<sdf version='1.6'>
  <model name='opendog'>

    <link name='ground_link'>
      <self_collide>1</self_collide>
      <pose>0 0.25 0 0 0 0</pose>
      <inertial>
        <pose>0 0 0 0 0 0</pose>
        <mass>1</mass>
        <inertia>
          <ixx>1</ixx>
          <ixy>1</ixy>
          <ixz>1</ixz>
          <iyy>1</iyy>
          <iyz>1</iyz>
          <izz>1</izz>
        </inertia>
      </inertial>
      <collision name='ground_link_collision'>
        <pose>0 0 0 0 0 0</pose>
        <geometry>
          <cylinder>
            <length>0.5</length>
            <radius>0.05</radius>
          </cylinder>
        </geometry>
      </collision>
      <visual name='ground_link_visual'>
        <pose>0 0 0 0 0 0</pose>
        <geometry>
          <cylinder>
            <length>0.5</length>
            <radius>0.05</radius>
          </cylinder>
        </geometry>
        <material>
          <script>
            <uri>file://media/materials/scripts/gazebo.material</uri>
            <name>Gazebo/Red</name>
          </script>
        </material>
      </visual>
    </link> 

    <!-- Commented out joint to world -->
    <!-- <joint name='1_to_world' type='revolute'>
      <child>ground_link</child>
      <parent>world</parent>
      <axis>
        <limit>
          <lower>0</lower>
          <upper>0</upper>
        </limit>
        <dynamics>
          <damping>0</damping>
          <friction>0</friction>
          <spring_reference>0</spring_reference>
          <spring_stiffness>0</spring_stiffness>
        </dynamics>
        <use_parent_model_frame>1</use_parent_model_frame>
        <xyz>0 0 1</xyz>
      </axis>
    </joint> -->

    <link name='left_link'>
      <pose>0 0.25 0.25 1.57079632679 0 0</pose>
      <inertial>
        <pose>0 0 -0.25 0 0 0</pose>
        <mass>1</mass>
        <inertia>
          <ixx>1</ixx>
          <ixy>1</ixy>
          <ixz>1</ixz>
          <iyy>1</iyy>
          <iyz>1</iyz>
          <izz>1</izz>
        </inertia>
      </inertial>
      <collision name='left_link_collision'>
        <pose>0 0 -0.25 0 -0 0</pose>
        <geometry>
          <cylinder>
            <length>0.5</length>
            <radius>0.05</radius>
          </cylinder>
        </geometry>
      </collision>
      <visual name='left_link_visual'>
        <pose>0 0 -0.25 0 -0 0</pose>
        <geometry>
          <cylinder>
            <length>0.5</length>
            <radius>0.05</radius>
          </cylinder>
        </geometry>
        <material>
          <script>
            <uri>file://media/materials/scripts/gazebo.material</uri>
            <name>Gazebo/Green</name>
          </script>
        </material>
      </visual>
    </link>

    <joint name='ground_joint1' type='revolute'>
      <child>left_link</child>
      <parent>ground_link</parent>
      <axis>
        <xyz>1 0 0</xyz>
         <limit>
          <lower>-1e+16</lower>
          <upper>1e+16</upper>
        </limit>
        <dynamics>
          <spring_reference>0</spring_reference>
          <spring_stiffness>0</spring_stiffness>
        </dynamics>
        <use_parent_model_frame>1</use_parent_model_frame> 
      </axis>
    </joint>

    <link name='top_link'>
      <pose>0 0.75 0.25 0 0 0</pose>
      <inertial>
        <pose>0 0 -0.25 0 0 0</pose>
        <mass>1</mass>
        <inertia>
          <ixx>1</ixx>
          <ixy>1</ixy>
          <ixz>1</ixz>
          <iyy>1</iyy>
          <iyz>1</iyz>
          <izz>1</izz>
        </inertia>
      </inertial>
      <collision name='top_link_collision'>
        <pose>0 0 -0.25 0 -0 0</pose>
        <geometry>
          <cylinder>
            <length>0.5</length>
            <radius>0.05</radius>
          </cylinder>
        </geometry>
      </collision>
      <visual name='top_link_visual'>
        <pose>0 0 -0.25 0 0 0</pose>
        <geometry>
          <cylinder>
            <length>0.5</length>
            <radius>0.05</radius>
          </cylinder>
        </geometry>
        <material>
          <script>
            <uri>file://media/materials/scripts/gazebo.material</uri>
            <name>Gazebo/Blue</name>
          </script>
        </material>
      </visual>
    </link>

    <!-- Joints are with respect to CHILD in SDF -->
    <joint name='ground_joint2' type='revolute'>
      <child>top_link</child>
      <parent>left_link</parent>
      <axis>
        <xyz>1 0 0</xyz>
         <limit>
          <lower>-1e+16</lower>
          <upper>1e+16</upper>
        </limit>
        <dynamics>
          <spring_reference>0</spring_reference>
          <spring_stiffness>0</spring_stiffness>
        </dynamics>
        <use_parent_model_frame>1</use_parent_model_frame> 
      </axis>
    </joint>

    <link name='right_link'>
      <pose>0 0.75 -.25 -1.57079632679 0 0</pose>
      <inertial>
        <pose frame=''>0 0 -0.25 0 0 0</pose>
        <mass>1</mass>
        <inertia>
          <ixx>1</ixx>
          <ixy>1</ixy>
          <ixz>1</ixz>
          <iyy>1</iyy>
          <iyz>1</iyz>
          <izz>1</izz>
        </inertia>
      </inertial>
      <collision name='right_link_collision'>
        <pose frame=''>0 0 -0.25 0 -0 0</pose>
        <geometry>
          <cylinder>
            <length>0.5</length>
            <radius>0.05</radius>
          </cylinder>
        </geometry>
      </collision>
      <visual name='right_link_visual'>
        <pose frame=''>0 0 -0.25 0 -0 0</pose>
        <geometry>
          <cylinder>
            <length>0.5</length>
            <radius>0.05</radius>
          </cylinder>
        </geometry>
        <material>
          <script>
            <uri>file://media/materials/scripts/gazebo.material</uri>
            <name>Gazebo/Yellow</name>
          </script>
        </material>
      </visual>
    </link>

    <joint name='top_joint1' type='revolute'>
      <child>right_link</child>
      <parent>top_link</parent>
      <axis>
        <xyz>1 0 0</xyz>
         <limit>
          <lower>-1e+16</lower>
          <upper>1e+16</upper>
        </limit>
        <dynamics>
          <spring_reference>0</spring_reference>
          <spring_stiffness>0</spring_stiffness>
        </dynamics>
        <use_parent_model_frame>1</use_parent_model_frame> 
      </axis>
    </joint>

    <!-- Commented out plugin -->
    <!-- <plugin name='gazebo_ros_control' filename='libgazebo_ros_control.so'>
      <robotNamespace>/opendog</robotNamespace>
    </plugin>
    <static>0</static> -->

    <!-- Closed Loop Joint -->
        <joint name='button' type='revolute'>
      <pose>0 0 -0.25 0 0 0 </pose>
      <child>ground_link</child>
      <parent>right_link</parent>
      <axis>
        <xyz>1 0 0</xyz>
         <limit> 
         <lower>-1e+16</lower>
          <upper>1e+16</upper>
        </limit> 
         <dynamics>
          <spring_reference>0</spring_reference>
          <spring_stiffness>0</spring_stiffness>
        </dynamics>
        <use_parent_model_frame>1</use_parent_model_frame>
        <use_parent_model_frame>1</use_parent_model_frame> 
      </axis>
    </joint>  
  </model>  
</sdf>
